Workbook

Sheet Operating Model
E2: Units | F2: Constants | G2: Constants | H2: Constants
C3: COPART
C4: Three Statement Model
D5: Forecast Period Start | G5: 45869
D6: Forecast Period | G6: 10
D7: Forecast Period End | G7: =EDATE(G5,G6*12) -> 49521
D8: Beginning Period | I8: =IF(H11,H8,H9+1) -> 44409 | J8: =IF(I11,I8,I9+1) -> 44774 | K8: =IF(J11,J8,J9+1) -> 45139 | L8: =IF(K11,K8,K9+1) -> 45505 | M8: =IF(L11,L8,L9+1) -> 45505 | N8: =IF(M11,M8,M9+1) -> 45870 | O8: =IF(N11,N8,N9+1) -> 46235 | P8: =IF(O11,O8,O9+1) -> 46600 | ... AH8: =IF(AG11,AG8,AG9+1) -> 53175
D9: Ending Period | H9: 44408 | I9: =EDATE(I8,12)-1 -> 44773 | J9: =EDATE(J8,12)-1 -> 45138 | K9: =EDATE(K8,12)-1 -> 45504 | L9: =EDATE(L8,12)-1 -> 45869 | M9: =EDATE(M8,12)-1 -> 45869 | N9: =EDATE(N8,12)-1 -> 46234 | O9: =EDATE(O8,12)-1 -> 46599 | P9: =EDATE(P8,12)-1 -> 46965 | ... AH9: =EDATE(AH8,12)-1 -> 53539
D10: Forecast Flag | I10: =AND(I9>$G$5,I9<=$G$7) -> FALSE | J10: =AND(J9>$G$5,J9<=$G$7) -> FALSE | K10: =AND(K9>$G$5,K9<=$G$7) -> FALSE | L10: =AND(L9>$G$5,L9<=$G$7) -> FALSE | M10: =AND(M9>$G$5,M9<=$G$7) -> FALSE | N10: =AND(N9>$G$5,N9<=$G$7) -> TRUE | O10: =AND(O9>$G$5,O9<=$G$7) -> TRUE | P10: =AND(P9>$G$5,P9<=$G$7) -> TRUE | ... AH10: =AND(AH9>$G$5,AH9<=$G$7) -> FALSE
D11: Preceeds TTM | I11: =AND(NOT(H11),I9=$G$5) -> FALSE | J11: =AND(NOT(I11),J9=$G$5) -> FALSE | K11: =AND(NOT(J11),K9=$G$5) -> FALSE | L11: =AND(NOT(K11),L9=$G$5) -> TRUE | M11: =AND(NOT(L11),M9=$G$5) -> FALSE | N11: =AND(NOT(M11),N9=$G$5) -> FALSE | O11: =AND(NOT(N11),O9=$G$5) -> FALSE | P11: =AND(NOT(O11),P9=$G$5) -> FALSE | ... AH11: =AND(NOT(AG11),AH9=$G$5) -> FALSE
D12: Period Labels | I12: =IF(AND(I9=$G$5,H11), "TTM", IF(I9<=$G$5, "Historical", IF(I9>$G$7, "", "Forecast"))) -> Historical | J12: =IF(AND(J9=$G$5,I11), "TTM", IF(J9<=$G$5, "Historical", IF(J9>$G$7, "", "Forecast"))) -> Historical | K12: =IF(AND(K9=$G$5,J11), "TTM", IF(K9<=$G$5, "Historical", IF(K9>$G$7, "", "Forecast"))) -> Historical | L12: =IF(AND(L9=$G$5,K11), "TTM", IF(L9<=$G$5, "Historical", IF(L9>$G$7, "", "Forecast"))) -> Historical | M12: =IF(AND(M9=$G$5,L11), "", IF(M9<=$G$5, "Historical", IF(M9>$G$7, "", "Forecast"))) | N12: =IF(AND(N9=$G$5,M11), "TTM", IF(N9<=$G$5, "Historical", IF(N9>$G$7, "", "Forecast"))) -> Forecast | O12: =IF(AND(O9=$G$5,N11), "TTM", IF(O9<=$G$5, "Historical", IF(O9>$G$7, "", "Forecast"))) -> Forecast | P12: =IF(AND(P9=$G$5,O11), "TTM", IF(P9<=$G$5, "Historical", IF(P9>$G$7, "", "Forecast"))) -> Forecast | Q12: =IF(AND(Q9=$G$5,P11), "TTM", IF(Q9<=$G$5, "Historical", IF(Q9>$G$7, "", "Forecast"))) -> Forecast | R12: =IF(AND(R9=$G$5,Q11), "TTM", IF(R9<=$G$5, "Historical", IF(R9>$G$7, "", "Forecast"))) -> Forecast | S12: =IF(AND(S9=$G$5,R11), "TTM", IF(S9<=$G$5, "Historical", IF(S9>$G$7, "", "Forecast"))) -> Forecast | T12: =IF(AND(T9=$G$5,S11), "TTM", IF(T9<=$G$5, "Historical", IF(T9>$G$7, "", "Forecast"))) -> Forecast | U12: =IF(AND(U9=$G$5,T11), "TTM", IF(U9<=$G$5, "Historical", IF(U9>$G$7, "", "Forecast"))) -> Forecast | ... AH12: =IF(AND(AH9=$G$5,AG11), "TTM", IF(AH9<=$G$5, "Historical", IF(AH9>$G$7, "", "Forecast")))
C14: Revenue Build
C16: Market Size | K16: 10600000 | L16: =R16/(1+F17)^5 -> 12196309 | M16: =L16 -> 12196309 | N16: 14100000 | O16: =N16+($R$16-$N$16)/4 -> 17375000 | P16: =O16+($R$16-$N$16)/4 -> 20650000 | Q16: =P16+($R$16-$N$16)/4 -> 23925000 | R16: 27200000
D17: Market Growth CAGR (2025-2030) | F17: 0.174
D18: Implied market shares | K18: =K65/K16 -> 0.39970028 | L18: =L65/L16 -> 0.38101347 | M18: =M65/M16 -> 0.38101347 | N18: =N65/N16 -> 0.35045492 | O18: =O65/O16 -> 0.30197357 | P18: =P65/P16 -> 0.26941281 | Q18: =Q65/Q16 -> 0.24624704 | R18: =R65/R16 -> 0.22909383
C20: Total Vehicles on Road - US | I20: 284000 | J20: 286000 | K20: 289000 | L20: 293000 | M20: =L20 -> 293000 | N20: =M20*(1+N21)*N10 -> 295930 | O20: =N20*(1+O21)*O10 -> 298889.3 | P20: =O20*(1+P21)*P10 -> 301878.19 | Q20: =P20*(1+Q21)*Q10 -> 304896.97 | R20: =Q20*(1+R21)*R10 -> 307945.94 | S20: =R20*(1+S21)*S10 -> 311025.4 | T20: =S20*(1+T21)*T10 -> 314135.66 | U20: =T20*(1+U21)*U10 -> 317277.01 | ... W20: =V20*(1+W21)*W10 -> 323654.28
D21: Growth Rate | J21: =J20/I20-1 -> 0.0070422535 | K21: =K20/J20-1 -> 0.01048951 | L21: =L20/K20-1 -> 0.01384083 | M21: 0 | N21: 0.01 | O21: =N21*O10 -> 0.01 | P21: =O21*P10 -> 0.01 | Q21: =P21*Q10 -> 0.01 | R21: =Q21*R10 -> 0.01 | S21: =R21*S10 -> 0.01 | T21: =S21*T10 -> 0.01 | U21: =T21*U10 -> 0.01 | V21: =U21*V10 -> 0.01 | W21: =V21*W10 -> 0.01
C22: Total Loss Frequency | I22: 0.228 | J22: 0.192 | K22: 0.221 | L22: 0.228 | M22: =L22 -> 0.228 | N22: 0.231 | O22: =(N22+0.3%)*O10 -> 0.234 | P22: =(O22+0.3%)*P10 -> 0.237 | Q22: =(P22+0.3%)*Q10 -> 0.24 | R22: =(Q22+0.3%)*R10 -> 0.243 | S22: =(R22+0.3%)*S10 -> 0.246 | T22: =(S22+0.3%)*T10 -> 0.249 | U22: =(T22+0.3%)*U10 -> 0.252 | V22: =(U22+0.3%)*V10 -> 0.255 | W22: =(V22+0.3%)*W10 -> 0.258 | X22: 0 | Y22: 0 | Z22: 0 | AA22: 0 | AB22: 0 | AC22: 0 | AD22: 0 | AE22: 0 | AF22: 0 | AG22: 0 | AH22: 0
D23: Scaler | I23: 0.06 | J23: 0.06 | K23: 0.06 | L23: 0.06 | M23: 0.06 | N23: =DCF!G10 -> 0.06 | O23: =N23 -> 0.06 | P23: =O23 -> 0.06 | Q23: =P23 -> 0.06 | R23: =Q23 -> 0.06 | S23: =R23 -> 0.06 | T23: =S23 -> 0.06 | U23: =T23 -> 0.06 | V23: =U23 -> 0.06 | W23: =V23 -> 0.06
C24: Units Sold | I24: =I20*I22*I23 -> 3885.12 | J24: =J20*J22*J23 -> 3294.72 | K24: =K20*K22*K23 -> 3832.14 | L24: =L20*L22*L23 -> 4008.24 | M24: =M20*M22*M23 -> 4008.24 | N24: =N20*N22*N23 -> 4101.5898 | O24: =O20*O22*O23 -> 4196.4058 | P24: =P20*P22*P23 -> 4292.7079 | ... W24: =W20*W22*W23 -> 5010.1683
C25: Units sold Growth | J25: =J24/I24-1 -> -0.15196442 | K25: =K24/J24-1 -> 0.16311553 | L25: =L24/K24-1 -> 0.045953436 | M25: =M24/L24-1 -> 0 | N25: =N24/M24-1 -> 0.023289474 | O25: =O24/N24-1 -> 0.023116883 | P25: =P24/O24-1 -> 0.022948718 | Q25: =Q24/P24-1 -> 0.02278481 | ... W25: =W24/V24-1 -> 0.021882353
C26: Revenue Per Vehicle | L26: =L61/L24 -> 990.12584 | M26: =M61/M24 -> 990.12584 | N26: =M26+($W$26-$M$26)/10 -> 1031.1133 | O26: =N26+($W$26-$M$26)/10 -> 1072.1007 | P26: =O26+($W$26-$M$26)/10 -> 1113.0881 | Q26: =P26+($W$26-$M$26)/10 -> 1154.0755 | R26: =Q26+($W$26-$M$26)/10 -> 1195.0629 | S26: =R26+($W$26-$M$26)/10 -> 1236.0503 | T26: =S26+($W$26-$M$26)/10 -> 1277.0378 | U26: =T26+($W$26-$M$26)/10 -> 1318.0252 | V26: =U26+($W$26-$M$26)/10 -> 1359.0126 | W26: 1400
C28: Income Statement
C30: =C58 -> Service revenues and vehicle sales:
C31: =C59 -> 0 | D31: =D59 -> United States | J31: =J59/I59-1 -> 0.12177493 | K31: =K59/J59-1 -> 0.10010448 | L31: =L59/K59-1 -> 0.10410921 | N31: =(N59/M59-1)*N10 -> 0.065649737 | O31: =(O59/N59-1)*O10 -> 0.057670636 | P31: =(P59/O59-1)*P10 -> 0.055915843 | Q31: =(Q59/P59-1)*Q10 -> 0.054279456 | R31: =(R59/Q59-1)*R10 -> 0.052749098 | S31: =(S59/R59-1)*S10 -> 0.051314074 | T31: =(T59/S59-1)*T10 -> 0.049965095 | U31: =(U59/T59-1)*U10 -> 0.048694052 | ... AH31: =(AH59/AG59-1)*AH10 -> #DIV/0!
C32: =C60 -> 0 | D32: =D60 -> International | J32: =J60/I60-1 -> 0.11445721 | K32: =K60/J60-1 -> 0.21996034 | L32: =L60/K60-1 -> 0.18901817 | N32: =(N60/M60-1)*N10 -> 0.065649737 | O32: =(O60/N60-1)*O10 -> 0.1046081 | P32: =(P60/O60-1)*P10 -> 0.10130616 | Q32: =(Q60/P60-1)*Q10 -> 0.098239957 | R32: =(R60/Q60-1)*R10 -> 0.095384617 | S32: =(S60/R60-1)*S10 -> 0.092718673 | T32: =(T60/S60-1)*T10 -> 0.090223497 | U32: =(U60/T60-1)*U10 -> 0.087882842 | ... AH32: =(AH60/AG60-1)*AH10 -> #DIV/0!
C33: =C61 -> Service revenues | J33: =J61/I61-1 -> 0.12095449 | K33: =K61/J61-1 -> 0.1134645 | L33: =L61/K61-1 -> 0.11447901 | N33: =(N61/M61-1)*N10 -> 0.065649737 | O33: =(O61/N61-1)*O10 -> 0.063786438 | P33: =(P61/O61-1)*P10 -> 0.062057008 | Q33: =(Q61/P61-1)*Q10 -> 0.060446974 | R33: =(R61/Q61-1)*R10 -> 0.058943903 | S33: =(S61/R61-1)*S10 -> 0.057537053 | T33: =(T61/S61-1)*T10 -> 0.056217096 | U33: =(U61/T61-1)*U10 -> 0.05497589 | ... AH33: =(AH61/AG61-1)*AH10 -> #DIV/0!
C34: =C62 -> 0 | D34: =D62 -> United States | J34: =J62/I62-1 -> -0.15529206 | K34: =K62/J62-1 -> -0.02693624 | L34: =L62/K62-1 -> 0.1916913 | N34: 0.05 | O34: =N34*O10 -> 0.05 | P34: =O34*P10 -> 0.05 | Q34: =P34*Q10 -> 0.05 | R34: =Q34*R10 -> 0.05 | S34: =R34*S10 -> 0.05 | T34: =S34*T10 -> 0.05 | U34: =T34*U10 -> 0.05 | V34: =U34*V10 -> 0.05 | ... AH34: =AG34*AH10 -> 0
C35: =C63 -> 0 | D35: =D63 -> International | J35: =J63/I63-1 -> 0.37087106 | K35: =K63/J63-1 -> 0.042689319 | L35: =L63/K63-1 -> -0.18517266 | N35: 0.05 | O35: =N35*O10 -> 0.05 | P35: =O35*P10 -> 0.05 | Q35: =P35*Q10 -> 0.05 | R35: =Q35*R10 -> 0.05 | S35: =R35*S10 -> 0.05 | T35: =S35*T10 -> 0.05 | U35: =T35*U10 -> 0.05 | V35: =U35*V10 -> 0.05 | ... AH35: =AG35*AH10 -> 0
C36: =C64 -> Vehicle sales | J36: =J64/I64-1 -> 0.036285985 | K36: =K64/J64-1 -> 0.0065997408 | L36: =L64/K64-1 -> 0.0036622123 | N36: =N64/M64-1 -> 0.05 | O36: =O64/N64-1 -> 0.05 | P36: =P64/O64-1 -> 0.05 | Q36: =Q64/P64-1 -> 0.05 | R36: =R64/Q64-1 -> 0.05 | S36: =S64/R64-1 -> 0.05 | T36: =T64/S64-1 -> 0.05 | U36: =U64/T64-1 -> 0.05 | ... AH36: =AH64/AG64-1 -> #DIV/0!
C37: =C65 -> Total service revenues and vehicle sales | J37: =J65/I65-1 -> 0.10528572 | K37: =K65/J65-1 -> 0.094922675 | L37: =L65/K65-1 -> 0.096802486 | N37: =N65/M65-1 -> 0.063365414 | O37: =O65/N65-1 -> 0.061799386 | P37: =P65/O65-1 -> 0.060338532 | Q37: =Q65/P65-1 -> 0.058972493 | R37: =R65/Q65-1 -> 0.05769226 | S37: =S65/R65-1 -> 0.056489961 | T37: =T65/S65-1 -> 0.055358686 | U37: =U65/T65-1 -> 0.054292345 | ... AH37: =AH65/AG65-1 -> #DIV/0!
C39: Historical CAGR | F39: =((L65/I65)^(1/3))-1 -> 0.098994398
C40: Forecasted CAGR | F40: =((W65/M65)^(1/10))-1 -> 0.057386981
C42: =C66 -> Operating expenses:
C43: =C67 -> Facility operations | I43: =I67/I$65 -> -0.37404357 | J43: =J67/J$65 -> -0.39230442 | K43: =K67/K$65 -> -0.40362413 | L43: =L67/L$65 -> -0.41840662 | M43: =L43 -> -0.41840662 | N43: =M43-1% -> -0.42840662 | O43: =N43-1% -> -0.43840662 | P43: =O43-1% -> -0.44840662 | Q43: =P43-1% -> -0.45840662 | R43: =Q43-1% -> -0.46840662 | S43: =R43-1% -> -0.47840662 | T43: =S43-1% -> -0.48840662 | U43: =T43-1% -> -0.49840662 | ... AH43: =AG43-1% -> -0.62840662
C44: =C68 -> Cost of vehicle sales | I44: =I68/I$65 -> -0.16715687 | J44: =J68/J$65 -> -0.15880479 | K44: =K68/K$65 -> -0.14621498 | L44: =L68/L$65 -> -0.12976166 | N44: -0.14 | O44: =N44 -> -0.14 | P44: =O44 -> -0.14 | Q44: =P44 -> -0.14 | R44: =Q44 -> -0.14 | S44: =R44 -> -0.14 | T44: =S44 -> -0.14 | U44: =T44 -> -0.14 | V44: =U44 -> -0.14 | ... AH44: =AG44 -> -0.14
C45: =C69 -> General and administrative | I45: =I69/I$65 -> -0.06604662 | J45: =J69/J$65 -> -0.064716587 | K45: =K69/K$65 -> -0.079122729 | L45: =L69/L$65 -> -0.086708122 | N45: =L45 -> -0.086708122 | O45: =N45 -> -0.086708122 | P45: =O45 -> -0.086708122 | Q45: =P45 -> -0.086708122 | R45: =Q45 -> -0.086708122 | S45: =R45 -> -0.086708122 | T45: =S45 -> -0.086708122 | U45: =T45 -> -0.086708122 | V45: =U45 -> -0.086708122 | ... AH45: =AG45 -> -0.086708122
C46: =C70 -> Total operating expenses | I46: =I70/I$65 -> -0.60724706 | J46: =J70/J$65 -> -0.6158258 | K46: =K70/K$65 -> -0.62896184 | L46: =L70/L$65 -> -0.63487641 | N46: =N70/N$65 -> -0.65511474 | O46: =O70/O$65 -> -0.66511474 | P46: =P70/P$65 -> -0.67511474 | Q46: =Q70/Q$65 -> -0.68511474 | R46: =R70/R$65 -> -0.69511474 | S46: =S70/S$65 -> -0.70511474 | T46: =T70/T$65 -> -0.71511474 | U46: =U70/U$65 -> -0.72511474 | ... AH46: =AH70/AH$65 -> #DIV/0!
C48: Effective tax rate | I48: =I77/I76 -> -0.18704892 | J48: =J77/J76 -> -0.20368095 | K48: =K77/K76 -> -0.20544372 | L48: =L77/L76 -> -0.18317234 | N48: =AVERAGE(I48:L48) -> -0.19483648 | O48: =N48 -> -0.19483648 | P48: =O48 -> -0.19483648 | Q48: =P48 -> -0.19483648 | R48: =Q48 -> -0.19483648 | S48: =R48 -> -0.19483648 | T48: =S48 -> -0.19483648 | U48: =T48 -> -0.19483648 | V48: =U48 -> -0.19483648 | ... AH48: =AG48 -> -0.19483648
C50: US % of Total Service Rev | I50: =I59/I$61 -> 0.88788275 | J50: =J59/J$61 -> 0.8885326 | K50: =K59/K$61 -> 0.87787145 | L50: =L59/L$61 -> 0.86970319 | N50: =L50 -> 0.86970319 | O50: =N50-0.5% -> 0.86470319 | P50: =O50-0.5% -> 0.85970319 | Q50: =P50-0.5% -> 0.85470319 | R50: =Q50-0.5% -> 0.84970319 | S50: =R50-0.5% -> 0.84470319 | T50: =S50-0.5% -> 0.83970319 | U50: =T50-0.5% -> 0.83470319 | V50: =U50-0.5% -> 0.82970319 | W50: =V50-0.5% -> 0.82470319 | X50: =W50 -> 0.82470319 | Y50: =X50 -> 0.82470319 | Z50: =Y50 -> 0.82470319 | AA50: =Z50 -> 0.82470319 | AB50: =AA50 -> 0.82470319 | AC50: =AB50 -> 0.82470319 | AD50: =AC50 -> 0.82470319 | AE50: =AD50 -> 0.82470319 | ... AH50: =AG50 -> 0.82470319
...

Sheet DCF
C2: Discounted CashFlow
D3: Period Labels | I3: =YEAR('Operating Model'!I9) -> 2022 | J3: =YEAR('Operating Model'!J9) -> 2023 | K3: =YEAR('Operating Model'!K9) -> 2024 | L3: =YEAR('Operating Model'!L9) -> 2025 | M3: =YEAR('Operating Model'!M9) -> 2025 | N3: =YEAR('Operating Model'!N9) -> 2026 | O3: =YEAR('Operating Model'!O9) -> 2027 | P3: =YEAR('Operating Model'!P9) -> 2028 | ... AH3: =YEAR('Operating Model'!AH9) -> 2046
D4: Forecast | I4: ='Operating Model'!I10 -> FALSE | J4: ='Operating Model'!J10 -> FALSE | K4: ='Operating Model'!K10 -> FALSE | L4: ='Operating Model'!L10 -> FALSE | M4: ='Operating Model'!M10 -> FALSE | N4: ='Operating Model'!N10 -> TRUE | O4: ='Operating Model'!O10 -> TRUE | P4: ='Operating Model'!P10 -> TRUE | ... AH4: ='Operating Model'!AH10 -> FALSE
D5: Forecast Periods | I5: =(H5+I4)*I4 -> 0 | J5: =(I5+J4)*J4 -> 0 | K5: =(J5+K4)*K4 -> 0 | L5: =(K5+L4)*L4 -> 0 | M5: =(L5+M4)*M4 -> 0 | N5: =(M5+N4)*N4 -> 1 | O5: =(N5+O4)*O4 -> 2 | P5: =(O5+P4)*P4 -> 3 | ... AH5: =(AG5+AH4)*AH4 -> 0
D6: Mid Year Discount Periods | I6: =(H5+0.5)*I4 -> 0 | J6: =(I5+0.5)*J4 -> 0 | K6: =(J5+0.5)*K4 -> 0 | L6: =(K5+0.5)*L4 -> 0 | M6: =(L5+0.5)*M4 -> 0 | N6: =(M5+0.5)*N4 -> 0.5 | O6: =(N5+0.5)*O4 -> 1.5 | P6: =(O5+0.5)*P4 -> 2.5 | ... AH6: =(AG5+0.5)*AH4 -> 0
C8: WACC | G8: =WACC!F34 -> 0.078425824 | I8: Intrinsic Value Per Share | L8: =G44 -> 39.026671
C9: PGR | G9: 0.04 | I9: Current Price | L9: =G45 -> 28.91
C10: Scaler | G10: 0.06
C12: Tax Rates | I12: ='Operating Model'!I48*I4 -> 0 | J12: ='Operating Model'!J48*J4 -> 0 | K12: ='Operating Model'!K48*K4 -> 0 | L12: ='Operating Model'!L48*L4 -> 0 | M12: ='Operating Model'!M48*M4 -> 0 | N12: ='Operating Model'!N48*N4 -> -0.19483648 | O12: ='Operating Model'!O48*O4 -> -0.19483648 | P12: ='Operating Model'!P48*P4 -> -0.19483648 | ... AH12: ='Operating Model'!AH48*AH4 -> 0
C14: EBIT | I14: ='Operating Model'!I71*I4 -> 0 | J14: ='Operating Model'!J71*J4 -> 0 | K14: ='Operating Model'!K71*K4 -> 0 | L14: ='Operating Model'!L71*L4 -> 0 | M14: ='Operating Model'!M71*M4 -> 0 | N14: ='Operating Model'!N71*N4 -> 1704221 | O14: ='Operating Model'!O71*O4 -> 1757072.9 | P14: ='Operating Model'!P71*P4 -> 1807458.3 | ... AH14: ='Operating Model'!AH71*AH4 -> 0
C15: Tax | I15: =I12*I14 -> 0 | J15: =J12*J14 -> 0 | K15: =K12*K14 -> 0 | L15: =L12*L14 -> 0 | M15: =M12*M14 -> 0 | N15: =N12*N14 -> -332044.42 | O15: =O12*O14 -> -342341.9 | P15: =P12*P14 -> -352158.82 | ... AH15: =AH12*AH14 -> 0
C16: NOPAT | I16: =I14+I15 -> 0 | J16: =J14+J15 -> 0 | K16: =K14+K15 -> 0 | L16: =L14+L15 -> 0 | M16: =M14+M15 -> 0 | N16: =N14+N15 -> 1372176.6 | O16: =O14+O15 -> 1414731 | P16: =P14+P15 -> 1455299.5 | ... AH16: =AH14+AH15 -> 0
C17: Depreciation | I17: =-PPE!I6*I4 -> 0 | J17: =-PPE!J6*J4 -> 0 | K17: =-PPE!K6*K4 -> 0 | L17: =-PPE!L6*L4 -> 0 | M17: =-PPE!M6*M4 -> 0 | N17: =-PPE!N6*N4 -> 244444.33 | O17: =-PPE!O6*O4 -> 270671.87 | P17: =-PPE!P6*P4 -> 296428.12 | ... AH17: =-PPE!AH6*AH4 -> 0
C18: Capex | I18: ='Operating Model'!I117*I4 -> 0 | J18: ='Operating Model'!J117*J4 -> 0 | K18: ='Operating Model'!K117*K4 -> 0 | L18: ='Operating Model'!L117*L4 -> 0 | M18: ='Operating Model'!M117*M4 -> 0 | N18: ='Operating Model'!N117*N4 -> -533206.67 | O18: ='Operating Model'!O117*O4 -> -524550.72 | P18: ='Operating Model'!P117*P4 -> -515124.95 | ... AH18: ='Operating Model'!AH117*AH4 -> 0
C19: Change in Net working capital | I19: =SUM('Operating Model'!I106:I114)*DCF!I4 -> 0 | J19: =SUM('Operating Model'!J106:J114)*DCF!J4 -> 0 | K19: =SUM('Operating Model'!K106:K114)*DCF!K4 -> 0 | L19: =SUM('Operating Model'!L106:L114)*DCF!L4 -> 0 | M19: =SUM('Operating Model'!M106:M114)*DCF!M4 -> 0 | N19: =SUM('Operating Model'!N106:N114)*DCF!N4 -> -37246.636 | O19: =SUM('Operating Model'!O106:O114)*DCF!O4 -> -16537.376 | P19: =SUM('Operating Model'!P106:P114)*DCF!P4 -> -16384.467 | ... AH19: =SUM('Operating Model'!AH106:AH114)*DCF!AH4 -> 0
C20: Unlevered Free Cash Flow | I20: =SUM(I16:I19) -> 0 | J20: =SUM(J16:J19) -> 0 | K20: =SUM(K16:K19) -> 0 | L20: =SUM(L16:L19) -> 0 | M20: =SUM(M16:M19) -> 0 | N20: =SUM(N16:N19) -> 1046167.6 | O20: =SUM(O16:O19) -> 1144314.8 | P20: =SUM(P16:P19) -> 1220218.2 | ... AH20: =SUM(AH16:AH19) -> 0
D21: % growth | J21: =IFERROR(J20/I20-1,0)*J4 -> 0 | K21: =IFERROR(K20/J20-1,0)*K4 -> 0 | L21: =IFERROR(L20/K20-1,0)*L4 -> 0 | M21: =IFERROR(M20/L20-1,0)*M4 -> 0 | N21: =IFERROR(N20/M20-1,0)*N4 -> 0 | O21: =IFERROR(O20/N20-1,0)*O4 -> 0.093815917 | P21: =IFERROR(P20/O20-1,0)*P4 -> 0.066330926 | Q21: =IFERROR(Q20/P20-1,0)*Q4 -> 0.060670544 | ... AH21: =IFERROR(AH20/AG20-1,0)*AH4 -> 0
C22: Discounting Factor | I22: =(1/(1+$G$8)^I6)*I4 -> 0 | J22: =(1/(1+$G$8)^J6)*J4 -> 0 | K22: =(1/(1+$G$8)^K6)*K4 -> 0 | L22: =(1/(1+$G$8)^L6)*L4 -> 0 | M22: =(1/(1+$G$8)^M6)*M4 -> 0 | N22: =(1/(1+$G$8)^N6)*N4 -> 0.96295249 | O22: =(1/(1+$G$8)^O6)*O4 -> 0.89292418 | P22: =(1/(1+$G$8)^P6)*P4 -> 0.8279885 | ... AH22: =(1/(1+$G$8)^AH6)*AH4 -> 0
C23: Discounted Free Cash Flow | I23: =I20*I22 -> 0 | J23: =J20*J22 -> 0 | K23: =K20*K22 -> 0 | L23: =L20*L22 -> 0 | M23: =M20*M22 -> 0 | N23: =N20*N22 -> 1007409.7 | O23: =O20*O22 -> 1021786.3 | P23: =P20*P22 -> 1010326.6 | ... AH23: =AH20*AH22 -> 0
D25: NOPAT growth | J25: =IFERROR(J16/I16-1,0)*J4 -> 0 | K25: =IFERROR(K16/J16-1,0)*K4 -> 0 | L25: =IFERROR(L16/K16-1,0)*L4 -> 0 | M25: =IFERROR(M16/L16-1,0)*M4 -> 0 | N25: =IFERROR(N16/M16-1,0)*N4 -> 0 | O25: =IFERROR(O16/N16-1,0)*O4 -> 0.031012352 | P25: =IFERROR(P16/O16-1,0)*P4 -> 0.02867579 | Q25: =IFERROR(Q16/P16-1,0)*Q4 -> 0.026377216 | ... AH25: =IFERROR(AH16/AG16-1,0)*AH4 -> 0
D26: Capex Growth | J26: =IFERROR(J18/I18-1,0)*J4 -> 0 | K26: =IFERROR(K18/J18-1,0)*K4 -> 0 | L26: =IFERROR(L18/K18-1,0)*L4 -> 0 | M26: =IFERROR(M18/L18-1,0)*M4 -> 0 | N26: =IFERROR(N18/M18-1,0)*N4 -> 0 | O26: =IFERROR(O18/N18-1,0)*O4 -> -0.016233766 | P26: =IFERROR(P18/O18-1,0)*P4 -> -0.017969231 | Q26: =IFERROR(Q18/P18-1,0)*Q4 -> -0.019831224 | ... AH26: =IFERROR(AH18/AG18-1,0)*AH4 -> 0
D27: Invested Capital | I27: =('Operating Model'!I188+'Operating Model'!I181+'Operating Model'!I177+'Operating Model'!I178-'Operating Model'!I154-'Operating Model'!I155)*I4 -> 0 | J27: =('Operating Model'!J188+'Operating Model'!J181+'Operating Model'!J177+'Operating Model'!J178-'Operating Model'!J154-'Operating Model'!J155)*J4 -> 0 | K27: =('Operating Model'!K188+'Operating Model'!K181+'Operating Model'!K177+'Operating Model'!K178-'Operating Model'!K154-'Operating Model'!K155)*K4 -> 0 | L27: =('Operating Model'!L188+'Operating Model'!L181+'Operating Model'!L177+'Operating Model'!L178-'Operating Model'!L154-'Operating Model'!L155)*L4 -> 0 | M27: =('Operating Model'!M188+'Operating Model'!M181+'Operating Model'!M177+'Operating Model'!M178-'Operating Model'!M154-'Operating Model'!M155)*M4 -> 0 | N27: =('Operating Model'!N188+'Operating Model'!N181+'Operating Model'!N177+'Operating Model'!N178-'Operating Model'!N154-'Operating Model'!N155)*N4 -> 4995033 | O27: =('Operating Model'!O188+'Operating Model'!O181+'Operating Model'!O177+'Operating Model'!O178-'Operating Model'!O154-'Operating Model'!O155)*O4 -> 5265449.2 | P27: =('Operating Model'!P188+'Operating Model'!P181+'Operating Model'!P177+'Operating Model'!P178-'Operating Model'!P154-'Operating Model'!P155)*P4 -> 5500530.5 | ... AH27: =('Operating Model'!AH188+'Operating Model'!AH181+'Operating Model'!AH177+'Operating Model'!AH178-'Operating Model'!AH154-'Operating Model'!AH155)*AH4 -> 0
D28: ROIC | I28: =IFERROR(I16/I27,0) -> 0 | J28: =IFERROR(J16/J27,0) -> 0 | K28: =IFERROR(K16/K27,0) -> 0 | L28: =IFERROR(L16/L27,0) -> 0 | M28: =IFERROR(M16/M27,0) -> 0 | N28: =IFERROR(N16/N27,0) -> 0.27470821 | O28: =IFERROR(O16/O27,0) -> 0.26868192 | P28: =IFERROR(P16/P27,0) -> 0.26457439 | ... AH28: =IFERROR(AH16/AH27,0) -> 0
D30: NOPAT CAGR | G30: =(W16/N16)^(1/9)-1 -> 0.021808904
D31: Capex CAGR | G31: =(W18/N18)^(1/9)-1 -> -0.031214982
D32: Unlevered FCF CAGR | G32: =(W20/N20)^(1/9)-1 -> 0.056103108
C34: Terminal Value | G34: =W20*(1+G9)/(G8-G9) -> 46277331
D35: Discounted Terminal Value | G35: =G34*W22 -> 22587109 | H35: =G35/$G$37 -> 0.70492361
C36: Dicounted FCF | G36: =SUM(I23:AH23) -> 9454815.7 | H36: =G36/$G$37 -> 0.29507639
C37: Enterprise Value | G37: =G35+G36 -> 32041925 | H37: =G37/$G$37 -> 1
C38: Cash | G38: ='Operating Model'!M154 -> 3354142
C39: ='Operating Model'!C155 -> Investment in held to maturity securities | G39: ='Operating Model'!M155 -> 845570
C40: Debt + leases | G40: =-'Operating Model'!M178-'Operating Model'!M177-'Operating Model'!M173 -> -93116
C41: Redeeemable Non-Controlling Interest | G41: =-'Operating Model'!M181 -> -17181
C42: Equity Value | G42: =SUM(G37:G41) -> 36131340
C43: Share Count | G43: =WACC!F5 -> 925811.48
C44: Intrinsic Value Per Share | G44: =G42/G43 -> 39.026671
C45: Current Price | G45: =WACC!F4 -> 28.91
C46: Valuation % | G46: =G44/G45-1 -> 0.34993672
G48: Intrinsic Values | M48: WACC
...

Sheet WACC
C2: WACC Calculations
E4: Share Price | F4: 28.91 | K4: Interest coverage | L4: Spread
E5: Share Count | F5: =925811.482 -> 925811.48 | K5: >8.5 | L5: 0.004
E6: Equity Value | F6: =F4*F5 -> 26765210 | K6: 6.50 - 8.50 | L6: 0.0055
E7: =DCF!C38 -> Cash | F7: =-DCF!G38 -> -3354142 | K7: 5.50 - 6.49 | L7: 0.007
E8: =DCF!C39 -> Investment in held to maturity securities | F8: =-DCF!G39 -> -845570 | K8: 4.25 - 5.49 | L8: 0.0078
E9: =DCF!C40 -> Debt + leases | F9: =-DCF!G40 -> 93116 | K9: 3.00 - 4.24 | L9: 0.0089
E10: =DCF!C41 -> Redeeemable Non-Controlling Interest | F10: =-DCF!G41 -> 17181 | K10: 2.50 - 2.99 | L10: 0.0111
E11: Enterprise Debt | F11: =SUM(F6:F10) -> 22675795 | K11: 2.25 - 2.49 | L11: 0.0138
K12: 2.00 - 2.24 | L12: 0.0184
E13: Ten Year Bond Yield | F13: 0.04643 | K13: 1.75 - 1.99 | L13: 0.0275
E14: Damodaran's US Default Spread | F14: 0.0023 | K14: 1.50 - 1.74 | L14: 0.0321
E15: Risk Free Rate | F15: =F13-F14 -> 0.04413 | K15: 1.25 - 1.49 | L15: 0.0509
K16: 0.80 - 1.24 | L16: 0.0885
E17: Lambda | F17: 1 | K17: 0.65 - 0.79 | L17: 0.1261
E18: Country Risk Premium | F18: 0.0023 | K18: 0.20 - 0.64 | L18: 0.16
E19: Mature Market ERP | F19: 0.0423 | K19: <0.2 | L19: 0.19
E20: Total ERP | F20: =F19+(F17*F18) -> 0.0446
K21: EBIT | L21: ='Operating Model'!L71 -> 1696714
E22: Debt to Equity | F22: =F9/F6 -> 0.0034789938 | K22: Interest Expense | L22: ='Operating Model'!L139 -> 2019
E23: Unlevered Average Beta | F23: =AVERAGE(M39:M59) -> 0.6832841 | K23: EBIT/Interest | L23: =L21/L22 -> 840.37345
E24: Damodaran's Unlevered Beta (Business and Consumer Services) | F24: 0.77
E26: useDamodaranBeta - True, False | F26: TRUE | K26: Company Default Spread | L26: =L5 -> 0.004
E27: Current Beta | F27: =IF(F26,F24,F23) -> 0.77
E28: Tax Rate | F28: 0.21
E29: Levered Beta | F29: =F27*(1+(1-F28)*F22) -> 0.77211627
E31: Cost of Equity | F31: =F15+F29*(F20) -> 0.078566386
E32: Cost of Debt | F32: =F15+L26 -> 0.04813
E34: WACC | F34: =F31*(F6/(F6+F9))+F32*(F9/(F6+F9)*(1-F28)) -> 0.078425824
C37: Beta Array
D38: Ticker | E38: Company | F38: Market Cap | G38: Total Debt | H38: Debt to Equity | I38: Beta | J38: Country | K38: Industry | L38: Corporate Tax Rate | M38: Unlevered Beta
D39: CVNA | E39: Carvana Co. | F39: 102468657152 | G39: 5696999936 | H39: =G39/F39 -> 0.055597488 | I39: 3.488 | J39: United States | K39: Auto & Truck Dealerships | L39: 0.21 | M39: =I39/(1+(1-L39)*H39) -> 3.3412458
D40: 3153.T | E40: Yashima Denki Co., Ltd. | F40: 64063557632 | G40: 700000000 | H40: =G40/F40 -> 0.010926649 | I40: 0.611 | J40: Japan | K40: Industrial Distribution | L40: 0.3 | M40: =I40/(1+(1-L40)*H40) -> 0.60636215
D41: EBAY | E41: eBay Inc. | F41: 48435957760 | G41: 7206000128 | H41: =G41/F41 -> 0.14877377 | I41: 1.355 | J41: United States | K41: Internet Retail | L41: 0.21 | M41: =I41/(1+(1-L41)*H41) -> 1.212494
D42: RBA | E42: RB Global, Inc. | F42: 20724011008 | G42: 4440399872 | H42: =G42/F42 -> 0.21426354 | I42: 0.552 | J42: United States | K42: Specialty Business Services | L42: 0.21 | M42: =I42/(1+(1-L42)*H42) -> 0.47209015
D43: PAG | E43: Penske Automotive Group, Inc. | F43: 14256066560 | G43: 9371199488 | H43: =G43/F43 -> 0.65734819 | I43: 0.833 | J43: United States | K43: Auto & Truck Dealerships | L43: 0.21 | M43: =I43/(1+(1-L43)*H43) -> 0.54827698
D44: 0881.HK | E44: Zhongsheng Group Holdings Limited | F44: 10639637504 | G44: 34658426880 | H44: =G44/F44 -> 3.2574819 | I44: 0.893 | J44: China | K44: Auto & Truck Dealerships | L44: 0.25 | M44: =I44/(1+(1-L44)*H44) -> 0.25935844
D45: AN | E45: AutoNation, Inc. | F45: 7004923904 | G45: 11331300352 | H45: =G45/F45 -> 1.6176193 | I45: 0.727 | J45: United States | K45: Auto & Truck Dealerships | L45: 0.21 | M45: =I45/(1+(1-L45)*H45) -> 0.31915091
D46: AUTO.L | E46: Autotrader Group plc | F46: 4180527616 | G46: 211000000 | H46: =G46/F46 -> 0.050472098 | I46: 0.693 | J46: United Kingdom | K46: Internet Content & Information | L46: 0.25 | M46: =I46/(1+(1-L46)*H46) -> 0.66772393
D47: ABG | E47: Asbury Automotive Group, Inc. | F47: 4005072640 | G47: 5530500096 | H47: =G47/F47 -> 1.3808739 | I47: 0.724 | J47: United States | K47: Auto & Truck Dealerships | L47: 0.21 | M47: =I47/(1+(1-L47)*H47) -> 0.34626397
...

Sheet PPE
D2: PPE and Depreciation | E2: Units | F2: Constants | G2: Constants | I2: 2022 | J2: 2023 | K2: 2024 | L2: 2025 | M2: 2025 | N2: 2026 | O2: 2027 | P2: 2028 | Q2: 2029 | R2: 2030 | S2: 2031 | T2: 2032 | U2: 2033 | V2: 2034 | W2: 2035 | X2: 2036 | Y2: 2037 | Z2: 2038 | AA2: 2039 | AB2: 2040 | AC2: 2041 | AD2: 2042 | AE2: 2043 | AF2: 2044 | AG2: 2045 | AH2: 2046
D3: Forecast Flag | I3: =DCF!I4 -> FALSE | J3: =DCF!J4 -> FALSE | K3: =DCF!K4 -> FALSE | L3: =DCF!L4 -> FALSE | M3: =DCF!M4 -> FALSE | N3: =DCF!N4 -> TRUE | O3: =DCF!O4 -> TRUE | P3: =DCF!P4 -> TRUE | ... AH3: =DCF!AH4 -> FALSE
D4: Beginning PPE | J4: =I7 -> 2485764 | K4: =J7 -> 2844339 | L4: =K7 -> 3175838 | M4: =L7 -> 3598093 | N4: =M7 -> 3598093 | O4: =N7 -> 3886855.3 | P4: =O7 -> 4140734.2 | Q4: =P7 -> 4359431 | ... AH4: =AG7 -> 4860601.6
D5: Capex | I5: =-'Operating Model'!I117 -> 337448 | J5: =-'Operating Model'!J117 -> 516636 | K5: =-'Operating Model'!K117 -> 510990 | L5: =-'Operating Model'!L117 -> 568990 | M5: =-'Operating Model'!M117 -> 0 | N5: =-'Operating Model'!N117 -> 533206.67 | O5: =-'Operating Model'!O117 -> 524550.72 | P5: =-'Operating Model'!P117 -> 515124.95 | ... AH5: =-'Operating Model'!AH117 -> 0
D6: Depreciation | I6: =-'Operating Model'!I97 -> -138605 | J6: =-'Operating Model'!J97 -> -159684 | K6: =-'Operating Model'!K97 -> -190256 | L6: =-'Operating Model'!L97 -> -217784 | M6: =-'Operating Model'!M97 -> 0 | N6: =-N24 -> -244444.33 | O6: =-O24 -> -270671.87 | P6: =-P24 -> -296428.12 | Q6: =-Q24 -> -321673.59 | R6: =-R24 -> -346367.77 | S6: =-S24 -> -370469.13 | T6: =-T24 -> -393935.06 | U6: =-U24 -> -416721.9 | ... AH6: =-AH24 -> 0
D7: Ending PPE | I7: ='Operating Model'!I162 -> 2485764 | J7: ='Operating Model'!J162 -> 2844339 | K7: ='Operating Model'!K162 -> 3175838 | L7: ='Operating Model'!L162 -> 3598093 | M7: =SUM(M4:M6) -> 3598093 | N7: =SUM(N4:N6) -> 3886855.3 | O7: =SUM(O4:O6) -> 4140734.2 | P7: =SUM(P4:P6) -> 4359431 | Q7: =SUM(Q4:Q6) -> 4542666.8 | R7: =SUM(R4:R6) -> 4690182.8 | S7: =SUM(S4:S6) -> 4801740.8 | T7: =SUM(T4:T6) -> 4877124.4 | ... AH7: =SUM(AH4:AH6) -> 4860601.6
D10: Existing PPE Depreciation Period | E10: Years | G10: =-L7/L6 -> 16.521384
D11: Capex average Depreciation Period | E11: Years | G11: 20
D13: Existing PPE Depreciation | G13: =M7/G10 -> 217784 | N13: =G13 -> 217784 | O13: =MAX(0,MIN($N$13,$M$7-SUM($N$13:N13)))*O3 -> 217784 | P13: =MAX(0,MIN($N$13,$M$7-SUM($N$13:O13)))*P3 -> 217784 | Q13: =MAX(0,MIN($N$13,$M$7-SUM($N$13:P13)))*Q3 -> 217784 | R13: =MAX(0,MIN($N$13,$M$7-SUM($N$13:Q13)))*R3 -> 217784 | S13: =MAX(0,MIN($N$13,$M$7-SUM($N$13:R13)))*S3 -> 217784 | T13: =MAX(0,MIN($N$13,$M$7-SUM($N$13:S13)))*T3 -> 217784 | U13: =MAX(0,MIN($N$13,$M$7-SUM($N$13:T13)))*U3 -> 217784 | V13: =MAX(0,MIN($N$13,$M$7-SUM($N$13:U13)))*V3 -> 217784 | ... AH13: =MAX(0,MIN($N$13,$M$7-SUM($N$13:AG13)))*AH3 -> 0
D14: 2026 | F14: {=TRANSPOSE(N5:W5)} -> 533206.67 | G14: =F14/$G$11 -> 26660.334 | N14: =G14 -> 26660.334 | O14: =MAX(0,MIN($N$14,$F$14-SUM($N$14:N14)))*O3 -> 26660.334 | P14: =MAX(0,MIN($N$14,$F$14-SUM($N$14:O14)))*P3 -> 26660.334 | Q14: =MAX(0,MIN($N$14,$F$14-SUM($N$14:P14)))*Q3 -> 26660.334 | R14: =MAX(0,MIN($N$14,$F$14-SUM($N$14:Q14)))*R3 -> 26660.334 | S14: =MAX(0,MIN($N$14,$F$14-SUM($N$14:R14)))*S3 -> 26660.334 | T14: =MAX(0,MIN($N$14,$F$14-SUM($N$14:S14)))*T3 -> 26660.334 | U14: =MAX(0,MIN($N$14,$F$14-SUM($N$14:T14)))*U3 -> 26660.334 | V14: =MAX(0,MIN($N$14,$F$14-SUM($N$14:U14)))*V3 -> 26660.334 | ... AH14: =MAX(0,MIN($N$14,$F$14-SUM($N$14:AG14)))*AH3 -> 0
D15: =D14+1 -> 2027 | F15: 524550.72 | G15: =F15/$G$11 -> 26227.536 | O15: =G15 -> 26227.536 | P15: =MAX(0,MIN($O$15,$F$15-SUM($O$15:O15)))*P3 -> 26227.536 | Q15: =MAX(0,MIN($O$15,$F$15-SUM($O$15:P15)))*Q3 -> 26227.536 | R15: =MAX(0,MIN($O$15,$F$15-SUM($O$15:Q15)))*R3 -> 26227.536 | S15: =MAX(0,MIN($O$15,$F$15-SUM($O$15:R15)))*S3 -> 26227.536 | T15: =MAX(0,MIN($O$15,$F$15-SUM($O$15:S15)))*T3 -> 26227.536 | U15: =MAX(0,MIN($O$15,$F$15-SUM($O$15:T15)))*U3 -> 26227.536 | V15: =MAX(0,MIN($O$15,$F$15-SUM($O$15:U15)))*V3 -> 26227.536 | W15: =MAX(0,MIN($O$15,$F$15-SUM($O$15:V15)))*W3 -> 26227.536 | ... AH15: =MAX(0,MIN($O$15,$F$15-SUM($O$15:AG15)))*AH3 -> 0
D16: =D15+1 -> 2028 | F16: 515124.95 | G16: =F16/$G$11 -> 25756.247 | P16: =G16 -> 25756.247 | Q16: =MAX(0,MIN($P$16,$F$16-SUM($P$16:P16)))*Q3 -> 25756.247 | R16: =MAX(0,MIN($P$16,$F$16-SUM($P$16:Q16)))*R3 -> 25756.247 | S16: =MAX(0,MIN($P$16,$F$16-SUM($P$16:R16)))*S3 -> 25756.247 | T16: =MAX(0,MIN($P$16,$F$16-SUM($P$16:S16)))*T3 -> 25756.247 | U16: =MAX(0,MIN($P$16,$F$16-SUM($P$16:T16)))*U3 -> 25756.247 | V16: =MAX(0,MIN($P$16,$F$16-SUM($P$16:U16)))*V3 -> 25756.247 | W16: =MAX(0,MIN($P$16,$F$16-SUM($P$16:V16)))*W3 -> 25756.247 | X16: =MAX(0,MIN($P$16,$F$16-SUM($P$16:W16)))*X3 -> 0 | ... AH16: =MAX(0,MIN($P$16,$F$16-SUM($P$16:AG16)))*AH3 -> 0
D17: =D16+1 -> 2029 | F17: 504909.39 | G17: =F17/$G$11 -> 25245.47 | Q17: =G17 -> 25245.47 | R17: =MAX(0,MIN($Q$17,$F$17-SUM($Q$17:Q17)))*R3 -> 25245.47 | S17: =MAX(0,MIN($Q$17,$F$17-SUM($Q$17:R17)))*S3 -> 25245.47 | T17: =MAX(0,MIN($Q$17,$F$17-SUM($Q$17:S17)))*T3 -> 25245.47 | U17: =MAX(0,MIN($Q$17,$F$17-SUM($Q$17:T17)))*U3 -> 25245.47 | V17: =MAX(0,MIN($Q$17,$F$17-SUM($Q$17:U17)))*V3 -> 25245.47 | W17: =MAX(0,MIN($Q$17,$F$17-SUM($Q$17:V17)))*W3 -> 25245.47 | X17: =MAX(0,MIN($Q$17,$F$17-SUM($Q$17:W17)))*X3 -> 0 | Y17: =MAX(0,MIN($Q$17,$F$17-SUM($Q$17:X17)))*Y3 -> 0 | ... AH17: =MAX(0,MIN($Q$17,$F$17-SUM($Q$17:AG17)))*AH3 -> 0
D18: =D17+1 -> 2030 | F18: 493883.71 | G18: =F18/$G$11 -> 24694.185 | R18: =G18 -> 24694.185 | S18: =MAX(0,MIN($R$18,$F$18-SUM($R$18:R18)))*S3 -> 24694.185 | T18: =MAX(0,MIN($R$18,$F$18-SUM($R$18:S18)))*T3 -> 24694.185 | U18: =MAX(0,MIN($R$18,$F$18-SUM($R$18:T18)))*U3 -> 24694.185 | V18: =MAX(0,MIN($R$18,$F$18-SUM($R$18:U18)))*V3 -> 24694.185 | W18: =MAX(0,MIN($R$18,$F$18-SUM($R$18:V18)))*W3 -> 24694.185 | X18: =MAX(0,MIN($R$18,$F$18-SUM($R$18:W18)))*X3 -> 0 | Y18: =MAX(0,MIN($R$18,$F$18-SUM($R$18:X18)))*Y3 -> 0 | Z18: =MAX(0,MIN($R$18,$F$18-SUM($R$18:Y18)))*Z3 -> 0 | ... AH18: =MAX(0,MIN($R$18,$F$18-SUM($R$18:AG18)))*AH3 -> 0
D19: =D18+1 -> 2031 | F19: 482027.17 | G19: =F19/$G$11 -> 24101.359 | S19: =G19 -> 24101.359 | T19: =MAX(0,MIN($S$19,$F$19-SUM($S$19:S19)))*T3 -> 24101.359 | U19: =MAX(0,MIN($S$19,$F$19-SUM($S$19:T19)))*U3 -> 24101.359 | V19: =MAX(0,MIN($S$19,$F$19-SUM($S$19:U19)))*V3 -> 24101.359 | W19: =MAX(0,MIN($S$19,$F$19-SUM($S$19:V19)))*W3 -> 24101.359 | X19: =MAX(0,MIN($S$19,$F$19-SUM($S$19:W19)))*X3 -> 0 | Y19: =MAX(0,MIN($S$19,$F$19-SUM($S$19:X19)))*Y3 -> 0 | Z19: =MAX(0,MIN($S$19,$F$19-SUM($S$19:Y19)))*Z3 -> 0 | AA19: =MAX(0,MIN($S$19,$F$19-SUM($S$19:Z19)))*AA3 -> 0 | ... AH19: =MAX(0,MIN($S$19,$F$19-SUM($S$19:AG19)))*AH3 -> 0
D20: =D19+1 -> 2032 | F20: 469318.67 | G20: =F20/$G$11 -> 23465.934 | T20: =G20 -> 23465.934 | U20: =MAX(0,MIN($T$20,$F$20-SUM($T$20:T20)))*U3 -> 23465.934 | V20: =MAX(0,MIN($T$20,$F$20-SUM($T$20:U20)))*V3 -> 23465.934 | W20: =MAX(0,MIN($T$20,$F$20-SUM($T$20:V20)))*W3 -> 23465.934 | X20: =MAX(0,MIN($T$20,$F$20-SUM($T$20:W20)))*X3 -> 0 | Y20: =MAX(0,MIN($T$20,$F$20-SUM($T$20:X20)))*Y3 -> 0 | Z20: =MAX(0,MIN($T$20,$F$20-SUM($T$20:Y20)))*Z3 -> 0 | AA20: =MAX(0,MIN($T$20,$F$20-SUM($T$20:Z20)))*AA3 -> 0 | AB20: =MAX(0,MIN($T$20,$F$20-SUM($T$20:AA20)))*AB3 -> 0 | ... AH20: =MAX(0,MIN($T$20,$F$20-SUM($T$20:AG20)))*AH3 -> 0
D21: =D20+1 -> 2033 | F21: 455736.7 | G21: =F21/$G$11 -> 22786.835 | U21: =G21 -> 22786.835 | V21: =MAX(0,MIN($U$21,$F$21-SUM($U$21:U21)))*V3 -> 22786.835 | W21: =MAX(0,MIN($U$21,$F$21-SUM($U$21:V21)))*W3 -> 22786.835 | X21: =MAX(0,MIN($U$21,$F$21-SUM($U$21:W21)))*X3 -> 0 | Y21: =MAX(0,MIN($U$21,$F$21-SUM($U$21:X21)))*Y3 -> 0 | Z21: =MAX(0,MIN($U$21,$F$21-SUM($U$21:Y21)))*Z3 -> 0 | AA21: =MAX(0,MIN($U$21,$F$21-SUM($U$21:Z21)))*AA3 -> 0 | AB21: =MAX(0,MIN($U$21,$F$21-SUM($U$21:AA21)))*AB3 -> 0 | AC21: =MAX(0,MIN($U$21,$F$21-SUM($U$21:AB21)))*AC3 -> 0 | ... AH21: =MAX(0,MIN($U$21,$F$21-SUM($U$21:AG21)))*AH3 -> 0
D22: =D21+1 -> 2034 | F22: 441259.35 | G22: =F22/$G$11 -> 22062.968 | V22: =G22 -> 22062.968 | W22: =MAX(0,MIN($V$22,$F$22-SUM($V$22:V22)))*W3 -> 22062.968 | X22: =MAX(0,MIN($V$22,$F$22-SUM($V$22:W22)))*X3 -> 0 | Y22: =MAX(0,MIN($V$22,$F$22-SUM($V$22:X22)))*Y3 -> 0 | Z22: =MAX(0,MIN($V$22,$F$22-SUM($V$22:Y22)))*Z3 -> 0 | AA22: =MAX(0,MIN($V$22,$F$22-SUM($V$22:Z22)))*AA3 -> 0 | AB22: =MAX(0,MIN($V$22,$F$22-SUM($V$22:AA22)))*AB3 -> 0 | AC22: =MAX(0,MIN($V$22,$F$22-SUM($V$22:AB22)))*AC3 -> 0 | AD22: =MAX(0,MIN($V$22,$F$22-SUM($V$22:AC22)))*AD3 -> 0 | ... AH22: =MAX(0,MIN($V$22,$F$22-SUM($V$22:AG22)))*AH3 -> 0
D23: =D22+1 -> 2035 | F23: 400813.46 | G23: =F23/$G$11 -> 20040.673 | W23: =G23 -> 20040.673 | X23: =MAX(0,MIN($W$23,$F$23-SUM($W$23:W23)))*X3 -> 0 | Y23: =MAX(0,MIN($W$23,$F$23-SUM($W$23:X23)))*Y3 -> 0 | Z23: =MAX(0,MIN($W$23,$F$23-SUM($W$23:Y23)))*Z3 -> 0 | AA23: =MAX(0,MIN($W$23,$F$23-SUM($W$23:Z23)))*AA3 -> 0 | AB23: =MAX(0,MIN($W$23,$F$23-SUM($W$23:AA23)))*AB3 -> 0 | AC23: =MAX(0,MIN($W$23,$F$23-SUM($W$23:AB23)))*AC3 -> 0 | AD23: =MAX(0,MIN($W$23,$F$23-SUM($W$23:AC23)))*AD3 -> 0 | AE23: =MAX(0,MIN($W$23,$F$23-SUM($W$23:AD23)))*AE3 -> 0 | ... AH23: =MAX(0,MIN($W$23,$F$23-SUM($W$23:AG23)))*AH3 -> 0
D24: Total Depreciation | I24: =SUM(I13:I23)*I3 -> 0 | J24: =SUM(J13:J23)*J3 -> 0 | K24: =SUM(K13:K23)*K3 -> 0 | L24: =SUM(L13:L23)*L3 -> 0 | M24: =SUM(M13:M23)*M3 -> 0 | N24: =SUM(N13:N23)*N3 -> 244444.33 | O24: =SUM(O13:O23)*O3 -> 270671.87 | P24: =SUM(P13:P23)*P3 -> 296428.12 | ... AH24: =SUM(AH13:AH23)*AH3 -> 0

Sheet Data >>

Sheet Service Rev Br-2022
A1: Service revenues
A2: United States | B2: $ | C2: 2,533,165 | D2: $ | E2: 2,017,504 | F2: $ | G2: 1,714,724
A3: International | C3: 319,875 | E3: 274,363 | G3: 232,416
A4: Total service revenues | B4: $ | C4: 2,853,040 | D4: $ | E4: 2,291,867 | F4: $ | G4: 1,947,140

Sheet 2022 - Vehicle Sales
A1: Vehicle sales
A2: United States | B2: $ | C2: 411,985 | D2: $ | E2: 254,568 | F2: $ | G2: 145,962
A3: International | C3: 235,896 | E3: 146,076 | G3: 112,481
A4: Total vehicle sales | B4: $ | C4: 647,881 | D4: $ | E4: 400,644 | F4: $ | G4: 258,443

Sheet 2022 k - BS
A1: ASSETS
A2: Current assets:
A3: Cash, cash equivalents, and restricted cash | B3: $ | C3: 1,384,236 | D3: $ | E3: 1,048,260
A4: Accounts receivable, net | C4: 578,573 | E4: 480,628
A5: Vehicle pooling costs | C5: 112,242 | E5: 94,449
A6: Inventories | C6: 58,791 | E6: 44,968
A7: Income taxes receivable | C7: 49,882 | E7: 20,012
A8: Prepaid expenses and other assets | C8: 18,731 | E8: 14,294
A9: Total current assets | C9: 2,202,455 | E9: 1,702,611
A10: Property and equipment, net | C10: 2,485,764 | E10: 2,296,624
A11: Operating lease right-of-use assets | C11: 116,303 | E11: 119,487
A12: Intangibles, net | C12: 54,680 | E12: 45,873
A13: Goodwill | C13: 401,954 | E13: 355,717
A14: Other assets | C14: 47,708 | E14: 41,831
A15: Total assets | B15: $ | C15: 5,308,864 | D15: $ | E15: 4,562,143
A17: LIABILITIES AND STOCKHOLDERS’ EQUITY
A18: Current liabilities:
A19: Accounts payable and accrued liabilities | B19: $ | C19: 399,034 | D19: $ | E19: 369,826
A20: Deferred revenue | C20: 20,061 | E20: 20,973
A21: Income taxes payable | C21: — | E21: 7,760
A22: Current portion of operating and finance lease liabilities | C22: 21,794 | E22: 22,472
A23: Total current liabilities | C23: 440,889 | E23: 421,031
A24: Deferred income taxes | C24: 80,060 | E24: 63,969
A25: Income taxes payable | C25: 64,637 | E25: 52,345
A26: Operating and finance lease liabilities, net of current portion | C26: 95,683 | E26: 97,961
A27: Long-term debt and other liabilities, net of discount | C27: 1,996 | E27: 397,636
A28: Total liabilities | C28: 683,265 | E28: 1,032,942
A30: Commitments and contingencies
A31: Stockholders’ equity:
A32: Preferred stock: $0.0001 par value—5,000,000 shares authorized; none issued | C32: — | E32: —
A33: Common stock: $0.0001 par value—400,000,000 shares authorized; 238,040,974 and 237,014,273 shares issued and outstanding, respectively | C33: 24 | E33: 24
A34: Additional paid-in capital | C34: 838,532 | E34: 761,834
A35: Accumulated other comprehensive loss | C35: (169,365) | E35: (100,860)
A36: Retained earnings | C36: 3,956,408 | E36: 2,868,203
A37: Total stockholders’ equity | C37: 4,625,599 | E37: 3,529,201
A38: Total liabilities and stockholders’ equity | B38: $ | C38: 5,308,864 | D38: $ | E38: 4,562,143

Sheet 2022 k - IS
A1: Service revenues and vehicle sales:
A2: Service revenues | B2: $ | C2: 2,853,040 | D2: $ | E2: 2,291,867 | F2: $ | G2: 1,947,140
A3: Vehicle sales | C3: 647,881 | E3: 400,644 | G3: 258,443
A4: Total service revenues and vehicle sales | C4: 3,500,921 | E4: 2,692,511 | G4: 2,205,583
A5: Operating expenses:
A6: Yard operations | C6: 1,309,497 | E6: 1,003,292 | G6: 972,487
A7: Cost of vehicle sales | C7: 585,203 | E7: 346,128 | G7: 225,294
A8: General and administrative | C8: 231,224 | E8: 206,665 | G8: 191,703
A9: Total operating expenses | C9: 2,125,924 | E9: 1,556,085 | G9: 1,389,484
A10: Operating income | C10: 1,374,997 | E10: 1,136,426 | G10: 816,099
A11: Other expense:
A12: Interest expense, net | C12: (16,688) | E12: (20,247) | G12: (18,871)
A13: Loss on extinguishment of debt | C13: (16,759) | E13: — | G13: —
A14: Other (expense) income, net | C14: (596) | E14: 5,667 | G14: 3,611
A15: Total other expense | C15: (34,043) | E15: ( 14,580) | G15: (15,260)
A16: Income before income taxes | C16: 1,340,954 | E16: 1,121,846 | G16: 800,839
A17: Income tax expense | C17: 250,824 | E17: 185,351 | G17: 100,932
A18: Net income | B18: $ | C18: 1,090,130 | D18: $ | E18: 936,495 | F18: $ | G18: 699,907
A20: Basic net income per common share | B20: $ | C20: 4.59 | D20: $ | E20: 3.96 | F20: $ | G20: 3.00
A21: Weighted average common shares outstanding | C21: 237,419 | E21: 236,252 | G21: 233,202
A23: Diluted net income per common share | B23: $ | C23: 4.52 | D23: $ | E23: 3.90 | F23: $ | G23: 2.93
A24: Diluted weighted average common shares outstanding | C24: 241,151 | E24: 240,290 | G24: 238,656

Sheet 2022 k - CF
A1: Cash flows from operating activities:
A2: Net income | B2: $ | C2: 1,090,130 | D2: $ | E2: 936,495 | F2: $ | G2: 699,907
A3: Adjustments to reconcile net income to net cash provided by operating activities:
A4: Depreciation and amortization, including debt cost | C4: 138,605 | E4: 123,084 | G4: 104,257
A5: Allowance for credit loss | C5: 1,349 | E5: (1,121) | G5: 1,670
A6: Equity in (earnings) losses of unconsolidated affiliates | C6: 284 | E6: (3,240) | G6: 1,401
A7: Stock-based compensation | C7: 38,965 | E7: 40,922 | G7: 23,322
A8: Gain on sale of property and equipment | C8: (939) | E8: (1,480) | G8: (1,913)
A9: Loss on extinguishment of debt | C9: 16,759 | E9: — | G9: —
A10: Deferred income taxes | C10: 17,017 | E10: (7,951) | G10: 23,082
A11: Changes in operating assets and liabilities, net of effects from acquisitions:
A12: Accounts receivable | C12: (97,750) | E12: (127,513) | G12: 15,993
A13: Vehicle pooling costs | C13: (18,342) | E13: (20,476) | G13: 2,590
A14: Inventories | C14: (10,851) | E14: (24,602) | G14: 1,348
A15: Prepaid expenses and other current and non-current assets | C15: (5,156) | E15: 7,025 | G15: 141
A16: Operating lease right-of-use assets and lease liabilities | C16: 715 | E16: 570 | G16: (572)
A17: Accounts payable and accrued liabilities | C17: 36,306 | E17: 44,613 | G17: 41,648
A18: Deferred revenue | C18: (574) | E18: 8,781 | G18: 1,615
A19: Income taxes receivable | C19: (29,884) | E19: 6,739 | G19: (7,216)
A20: Income taxes payable | C20: 49 | E20: 9,045 | G20: 10,114
A21: Other liabilities | C21: — | E21: — | G21: 498
A22: Net cash provided by operating activities | C22: 1,176,683 | E22: 990,891 | G22: 917,885
A23: Cash flows from investing activities:
A24: Purchases of property and equipment | C24: (337,448) | E24: ( 462,996) | G24: (591,972)
A25: Purchases of assets and liabilities in connection with acquisitions | C25: (106,604) | E25: (5,000) | G25: (11,702)
A26: Proceeds from sale of property and equipment | C26: 4,333 | E26: 2,530 | G26: 2,466
A27: Investment in unconsolidated affiliate | C27: (2,591) | E27: — | G27: —
A28: Purchase of held to maturity securities | C28: (374,866) | E28: — | G28: —
A29: Proceeds from the sale of held to maturity securities | C29: 374,866 | E29: — | G29: —
A30: Net cash used in investing activities | C30: (442,310) | E30: (465,466) | G30: (601,208)
A31: Cash flows from financing activities:
A32: Proceeds from the exercise of stock options | C32: 28,108 | E32: 39,049 | G32: 71,640
A33: Proceeds from the issuance of Employee Stock Purchase Plan shares | C33: 9,625 | E33: 9,136 | G33: 8,276
A34: Payments for employee stock-based tax withholdings | C34: (1,925) | E34: (6,145) | G34: (103,451)
A35: Debt offering costs | C35: (1,212) | E35: — | G35: (2,814)
A36: Principal payments on long-term debt | C36: (416,759) | E36: — | G36: —
A37: Payments of finance lease obligations | C37: (530) | E37: (1,118) | G37: (1,065)
A38: Net cash (used in) provided by financing activities | C38: (382,693) | E38: 40,922 | G38: (27,414)
A39: Effect of foreign currency translation | C39: (15,704) | E39: 4,195 | G39: 2,136
A40: Net increase in cash, cash equivalents, and restricted cash | C40: 335,976 | E40: 570,542 | G40: 291,399
...

Sheet 2022 k - PPE
A1: Land | B1: $ | C1: 1,526,446 | D1: $ | E1: 1,428,262
A2: Buildings and improvements | C2: 1,209,331 | E2: 1,126,414
A3: Transportation and other equipment | C3: 429,405 | E3: 326,622
A4: Office furniture and equipment | C4: 84,728 | E4: 79,928
A5: Software | C5: 78,216 | E5: 66,170
C6: 3,328,126 | E6: 3,027,396
A7: Less: Accumulated depreciation and amortization | C7: (842,362) | E7: (730,772)
A8: Property and equipment, net | B8: $ | C8: 2,485,764 | D8: $ | E8: 2,296,624

Sheet 2022 k - Shares
A1: Weighted average common shares outstanding | B1: 237,419 | C1: 236,252 | D1: 233,202
A2: Effect of dilutive securities | B2: 3,732 | C2: 4,038 | D2: 5,454
A3: Weighted average common and dilutive potential common shares outstanding | B3: 241,151 | C3: 240,290 | D3: 238,656

Sheet 2022 k - T61
A1: Service revenues | C1: $ | D1: 2,533,165 | E1: $ | F1: 319,875 | G1: $ | H1: 2,853,040
A2: Vehicle sales | D2: 411,985 | F2: 235,896 | H2: 647,881
A3: Total service revenues and vehicle sales | D3: 2,945,150 | F3: 555,771 | H3: 3,500,921
A4: Yard operations | D4: 1,123,986 | F4: 185,511 | H4: 1,309,497
A5: Cost of vehicle sales | D5: 380,928 | F5: 204,275 | H5: 585,203
A6: General and administrative | D6: 192,667 | F6: 38,557 | H6: 231,224
A7: Operating income | C7: $ | D7: 1,247,569 | E7: $ | F7: 127,428 | G7: $ | H7: 1,374,997
A9: Depreciation and amortization, excluding debt costs | C9: $ | D9: 120,635 | E9: $ | F9: 17,350 | G9: $ | H9: 137,985
A10: Capital expenditures, including acquisitions | D10: 297,632 | F10: 146,420 | H10: 444,052
A11: Total assets | D11: 4,615,788 | F11: 693,076 | H11: 5,308,864
A12: Goodwill | D12: 270,269 | F12: 131,685 | H12: 401,954

Sheet 2022 k - T62
A1: Service revenues | D1: $ | E1: 2,017,504 | F1: $ | G1: 274,363 | H1: $ | I1: 2,291,867
A2: Vehicle sales | E2: 254,568 | G2: 146,076 | I2: 400,644
A3: Total service revenues and vehicle sales | E3: 2,272,072 | G3: 420,439 | I3: 2,692,511
A4: Yard operations | E4: 849,037 | G4: 154,255 | I4: 1,003,292
A5: Cost of vehicle sales | E5: 227,365 | G5: 118,763 | I5: 346,128
A6: General and administrative | E6: 172,115 | G6: 34,550 | I6: 206,665
A7: Operating income | D7: $ | E7: 1,023,555 | F7: $ | G7: 112,871 | H7: $ | I7: 1,136,426
A9: Depreciation and amortization, excluding debt costs | D9: $ | E9: 107,765 | F9: $ | G9: 14,206 | H9: $ | I9: 121,971
A10: Capital expenditures, including acquisitions | E10: 390,706 | G10: 77,290 | I10: 467,996
A11: Total assets | E11: 3,900,712 | G11: 661,431 | I11: 4,562,143
A12: Goodwill | E12: 270,305 | G12: 85,412 | I12: 355,717

Sheet 2022 k - T63
A1: Service revenues | D1: $ | E1: 1,714,724 | F1: $ | G1: 232,416 | H1: $ | I1: 1,947,140
A2: Vehicle sales | E2: 145,962 | G2: 112,481 | I2: 258,443
A3: Total service revenues and vehicle sales | E3: 1,860,686 | G3: 344,897 | I3: 2,205,583
A4: Yard operations | E4: 828,066 | G4: 144,421 | I4: 972,487
A5: Cost of vehicle sales | E5: 135,095 | G5: 90,199 | I5: 225,294
A6: General and administrative | E6: 154,346 | G6: 37,357 | I6: 191,703
A7: Operating income | D7: $ | E7: 743,179 | F7: $ | G7: 72,920 | H7: $ | I7: 816,099
A9: Depreciation and amortization, excluding debt costs | D9: $ | E9: 90,818 | F9: $ | G9: 10,572 | H9: $ | I9: 101,390
A10: Capital expenditures, including acquisitions | E10: 568,773 | G10: 34,901 | I10: 603,674

Sheet 2023 k - Service Rev
A1: Service revenues
A2: United States | B2: $ | C2: 2,841,641 | D2: $ | E2: 2,533,165 | F2: $ | G2: 2,017,504
A3: International | C3: 356,487 | E3: 319,875 | G3: 274,363
A4: Total service revenues | B4: $ | C4: 3,198,128 | D4: $ | E4: 2,853,040 | F4: $ | G4: 2,291,867

Sheet 2023 k - Vehicle Sales
A1: Vehicle sales
A2: United States | B2: $ | C2: 348,007 | D2: $ | E2: 411,985 | F2: $ | G2: 254,568
A3: International | C3: 323,383 | E3: 235,896 | G3: 146,076
A4: Total vehicle sales | B4: $ | C4: 671,390 | D4: $ | E4: 647,881 | F4: $ | G4: 400,644

Sheet 2023 k - BS
A1: ASSETS
A2: Current assets:
A3: Cash, cash equivalents, and restricted cash | B3: $ | C3: 957,395 | D3: $ | E3: 1,384,236
A4: Investment in held to maturity securities | C4: 1,406,589 | E4: —
A5: Accounts receivable, net | C5: 702,038 | E5: 578,573
A6: Vehicle pooling costs | C6: 123,725 | E6: 112,242
A7: Inventories | C7: 39,973 | E7: 58,791
A8: Income taxes receivable | C8: 6,574 | E8: 49,882
A9: Prepaid expenses and other assets | C9: 26,310 | E9: 18,731
A10: Total current assets | C10: 3,262,604 | E10: 2,202,455
A11: Property and equipment, net | C11: 2,844,339 | E11: 2,485,764
A12: Operating lease right-of-use assets | C12: 108,139 | E12: 116,303
A13: Intangibles, net | C13: 62,702 | E13: 54,680
A14: Goodwill | C14: 394,289 | E14: 401,954
A15: Other assets | C15: 65,806 | E15: 47,708
A16: Total assets | B16: $ | C16: 6,737,879 | D16: $ | E16: 5,308,864
A18: LIABILITIES AND STOCKHOLDERS’ EQUITY
A19: Current liabilities:
A20: Accounts payable and accrued liabilities | B20: $ | C20: 440,810 | D20: $ | E20: 399,034
A21: Deferred revenue | C21: 26,117 | E21: 20,061
A22: Income taxes payable | C22: 4,374 | E22: —
A23: Current portion of operating and finance lease liabilities | C23: 21,468 | E23: 21,794
A24: Total current liabilities | C24: 492,769 | E24: 440,889
A25: Deferred income taxes | C25: 89,492 | E25: 80,060
A26: Income taxes payable | C26: 69,193 | E26: 64,637
A27: Operating and finance lease liabilities, net of current portion | C27: 88,082 | E27: 95,683
A28: Long-term debt and other liabilities, net of discount | C28: 10,903 | E28: 1,996
A29: Total liabilities | C29: 750,439 | E29: 683,265
A31: Commitments and contingencies
A32: Stockholders’ equity:
A33: Preferred stock: $0.0001 par value—5,000,000 shares authorized; none issued | C33: — | E33: —
A34: Common stock: $0.0001 par value—1,600,000,000 shares authorized; 957,344,162 and 952,163,896 shares issued and outstanding, respectively | C34: 96 | E34: 96
A35: Additional paid-in capital | C35: 938,910 | E35: 838,460
A36: Accumulated other comprehensive loss | C36: (141,006) | E36: (169,365)
A37: Retained earnings | C37: 5,189,440 | E37: 3,956,408
A38: Total stockholders’ equity | C38: 5,987,440 | E38: 4,625,599
A39: Total liabilities and stockholders’ equity | B39: $ | C39: 6,737,879 | D39: $ | E39: 5,308,864

Sheet 2023 k - IS
A1: Service revenues and vehicle sales:
A2: Service revenues | B2: $ | C2: 3,198,128 | D2: $ | E2: 2,853,040 | F2: $ | G2: 2,291,867
A3: Vehicle sales | C3: 671,390 | E3: 647,881 | G3: 400,644
A4: Total service revenues and vehicle sales | C4: 3,869,518 | E4: 3,500,921 | G4: 2,692,511
A5: Operating expenses:
A6: Yard operations | C6: 1,518,029 | E6: 1,309,497 | G6: 1,003,292
A7: Cost of vehicle sales | C7: 614,498 | E7: 585,203 | G7: 346,128
A8: General and administrative | C8: 250,422 | E8: 231,224 | G8: 206,665
A9: Total operating expenses | C9: 2,382,949 | E9: 2,125,924 | G9: 1,556,085
A10: Operating income | C10: 1,486,569 | E10: 1,374,997 | G10: 1,136,426
A11: Other income (expense):
A12: Interest income (expense), net | C12: 65,928 | E12: ( 16,688) | G12: (20,247)
A13: Loss on extinguishment of debt | C13: — | E13: (16,759) | G13: —
A14: Other income (expense), net | C14: 1,831 | E14: (596) | G14: 5,667
A15: Total other income (expense) | C15: 67,759 | E15: (34,043) | G15: (14,580)
A16: Income before income taxes | C16: 1,554,328 | E16: 1,340,954 | G16: 1,121,846
A17: Income tax expense | C17: 316,587 | E17: 250,824 | G17: 185,351
A18: Net income | B18: $ | C18: 1,237,741 | D18: $ | E18: 1,090,130 | F18: $ | G18: 936,495
A20: Basic net income per common share | B20: $ | C20: 1.30 | D20: $ | E20: 1.15 | F20: $ | G20: 0.99
A21: Weighted average common shares outstanding | C21: 953,574 | E21: 949,676 | G21: 945,008
A23: Diluted net income per common share | B23: $ | C23: 1.28 | D23: $ | E23: 1.13 | F23: $ | G23: 0.97
A24: Diluted weighted average common shares outstanding | C24: 966,647 | E24: 964,604 | G24: 961,160

Sheet 2023 k - CF
A1: Cash flows from operating activities:
A2: Net income | B2: $ | C2: 1,237,741 | D2: $ | E2: 1,090,130 | F2: $ | G2: 936,495
A3: Adjustments to reconcile net income to net cash provided by operating activities:
A4: Depreciation and amortization, including debt cost | C4: 159,684 | E4: 138,605 | G4: 123,084
A5: Allowance for credit losses (gains) | C5: 1,946 | E5: 1,349 | G5: (1,121)
A6: Equity in losses (earnings) of unconsolidated affiliates | C6: 5,347 | E6: 284 | G6: (3,240)
A7: Stock-based compensation | C7: 39,673 | E7: 38,965 | G7: 40,922
A8: Gain on sale of property and equipment | C8: (1,846) | E8: (939) | G8: (1,480)
A9: Loss on extinguishment of debt | C9: — | E9: 16,759 | G9: —
A10: Deferred income taxes (benefits) | C10: 9,946 | E10: 17,017 | G10: (7,951)
A11: Changes in operating assets and liabilities, net of effects from acquisitions:
A12: Accounts receivable | C12: (123,207) | E12: (97,750) | G12: (127,513)
A13: Vehicle pooling costs | C13: (10,989) | E13: (18,342) | G13: (20,476)
A14: Inventories | C14: 26,549 | E14: (10,851) | G14: (24,602)
A15: Prepaid expenses and other current and non-current assets | C15: (59,949) | E15: (5,156) | G15: 7,025
A16: Operating lease right-of-use assets and lease liabilities | C16: 350 | E16: 715 | G16: 570
A17: Accounts payable and accrued liabilities | C17: 18,010 | E17: 36,306 | G17: 44,613
A18: Deferred revenue | C18: 5,896 | E18: (574) | G18: 8,781
A19: Income taxes receivable | C19: 33,193 | E19: (29,884) | G19: 6,739
A20: Income taxes payable | C20: 21,866 | E20: 49 | G20: 9,045
A21: Net cash provided by operating activities | C21: 1,364,210 | E21: 1,176,683 | G21: 990,891
A22: Cash flows from investing activities:
A23: Purchases of property and equipment | C23: (516,636) | E23: (337,448) | G23: (462,996)
A24: Proceeds from sale of property and equipment | C24: 33,919 | E24: 4,333 | G24: 2,530
A25: Purchases of assets and liabilities in connection with acquisitions | C25: — | E25: (106,604) | G25: (5,000)
A26: Investment in held to maturity securities | C26: (1,406,588) | E26: (374,866) | G26: —
A27: Proceeds from the sale of held to maturity securities | C27: — | E27: 374,866 | G27: —
A28: Investment in unconsolidated affiliate | C28: (2,744) | E28: (2,591) | G28: —
A29: Net cash used in investing activities | C29: (1,892,049) | E29: (442,310) | G29: (465,466)
A30: Cash flows from financing activities:
A31: Proceeds from the exercise of stock options | C31: 49,679 | E31: 28,108 | G31: 39,049
A32: Proceeds from the issuance of Employee Stock Purchase Plan shares | C32: 11,098 | E32: 9,625 | G32: 9,136
A33: Payments for employee stock-based tax withholdings | C33: (4,709) | E33: (1,925) | G33: (6,145)
A34: Issuance of principal on revolver facility | C34: 44,494 | E34: — | G34: —
A35: Principal payments on revolver facility | C35: (33,924) | E35: — | G35: —
A36: Debt offering costs | C36: — | E36: (1,212) | G36: —
A37: Principal payments on long-term debt | C37: — | E37: (416,759) | G37: —
A38: Payments of finance lease obligations | C38: (23) | E38: (530) | G38: (1,118)
A39: Net cash provided by (used in) financing activities | C39: 66,615 | E39: (382,693) | G39: 40,922
A40: Effect of foreign currency translation | C40: 34,383 | E40: (15,704 ) | G40: 4,195
...

Sheet 2023 k - PPE
A1: Land | B1: $ | C1: 1,812,001 | D1: $ | F1: 1,526,446
A2: Buildings and improvements | C2: 1,339,820 | F2: 1,209,331
A3: Transportation and other equipment | C3: 490,136 | F3: 429,405
A4: Office furniture and equipment | C4: 91,031 | F4: 84,728
A5: Software | C5: 89,575 | F5: 78,216
C6: 3,822,563 | F6: 3,328,126
A7: Less: Accumulated depreciation and amortization | C7: (978,224) | F7: (842,362)
A8: Property and equipment, net | B8: $ | C8: 2,844,339 | D8: $ | F8: 2,485,764

Sheet 2023 k - Shares
A1: Weighted average common shares outstanding | B1: 953,574 | C1: 949,676 | D1: 945,008
A2: Effect of dilutive securities | B2: 13,073 | C2: 14,928 | D2: 16,152
A3: Weighted average common and dilutive potential common shares outstanding | B3: 966,647 | C3: 964,604 | D3: 961,160

Sheet 2023 k - T59
A1: Service revenues | C1: $ | D1: 2,841,641 | E1: $ | F1: 356,487 | G1: $ | H1: 3,198,128
A2: Vehicle sales | D2: 348,007 | F2: 323,383 | H2: 671,390
A3: Total service revenues and vehicle sales | D3: 3,189,648 | F3: 679,870 | H3: 3,869,518
A4: Yard operations | D4: 1,292,527 | F4: 225,502 | H4: 1,518,029
A5: Cost of vehicle sales | D5: 326,764 | F5: 287,734 | H5: 614,498
A6: General and administrative | D6: 202,260 | F6: 48,162 | H6: 250,422
A7: Operating income | C7: $ | D7: 1,368,097 | E7: $ | F7: 118,472 | G7: $ | H7: 1,486,569
A9: Depreciation and amortization, excluding debt costs | C9: $ | D9: 135,804 | E9: $ | F9: 23,674 | G9: $ | H9: 159,478
A10: Capital expenditures, including acquisitions | D10: 373,190 | F10: 143,446 | H10: 516,636
A11: Total assets | D11: 5,825,064 | F11: 912,815 | H11: 6,737,879
A12: Goodwill | D12: 270,269 | F12: 124,020 | H12: 394,289

Sheet 2023 k - T60
A1: Service revenues | D1: $ | E1: 2,533,165 | F1: $ | G1: 319,875 | H1: $ | I1: 2,853,040
A2: Vehicle sales | E2: 411,985 | G2: 235,896 | I2: 647,881
A3: Total service revenues and vehicle sales | E3: 2,945,150 | G3: 555,771 | I3: 3,500,921
A4: Yard operations | E4: 1,123,986 | G4: 185,511 | I4: 1,309,497
A5: Cost of vehicle sales | E5: 380,928 | G5: 204,275 | I5: 585,203
A6: General and administrative | E6: 192,667 | G6: 38,557 | I6: 231,224
A7: Operating income | D7: $ | E7: 1,247,569 | F7: $ | G7: 127,428 | H7: $ | I7: 1,374,997
A9: Depreciation and amortization, excluding debt costs | D9: $ | E9: 120,635 | F9: $ | G9: 17,350 | H9: $ | I9: 137,985
A10: Capital expenditures, including acquisitions | E10: 297,632 | G10: 146,420 | I10: 444,052
A11: Total assets | E11: 4,615,788 | G11: 693,076 | I11: 5,308,864
A12: Goodwill | E12: 270,269 | G12: 131,685 | I12: 401,954

Sheet 2023 k - T61
A1: Service revenues | D1: $ | E1: 2,017,504 | F1: $ | G1: 274,363 | H1: $ | I1: 2,291,867
A2: Vehicle sales | E2: 254,568 | G2: 146,076 | I2: 400,644
A3: Total service revenues and vehicle sales | E3: 2,272,072 | G3: 420,439 | I3: 2,692,511
A4: Yard operations | E4: 849,037 | G4: 154,255 | I4: 1,003,292
A5: Cost of vehicle sales | E5: 227,365 | G5: 118,763 | I5: 346,128
A6: General and administrative | E6: 172,115 | G6: 34,550 | I6: 206,665
A7: Operating income | D7: $ | E7: 1,023,555 | F7: $ | G7: 112,871 | H7: $ | I7: 1,136,426
A9: Depreciation and amortization, excluding debt costs | D9: $ | E9: 107,765 | F9: $ | G9: 14,206 | H9: $ | I9: 121,971
A10: Capital expenditures, including acquisitions | E10: 390,706 | G10: 77,290 | I10: 467,996

Sheet 2024 k - Service Rev
A1: Service revenues
A2: United States | B2: $ | C2: 3,126,102 | D2: $ | E2: 2,841,641 | F2: $ | G2: 2,533,165
A3: International | C3: 434,900 | E3: 356,487 | G3: 319,875
A4: Total service revenues | B4: $ | C4: 3,561,002 | D4: $ | E4: 3,198,128 | F4: $ | G4: 2,853,040

Sheet 2024 k - Vehicle Sales
A1: Vehicle sales
A2: United States | B2: $ | C2: 338,633 | D2: $ | E2: 348,007 | F2: $ | G2: 411,985
A3: International | C3: 337,188 | E3: 323,383 | G3: 235,896
A4: Total vehicle sales | B4: $ | C4: 675,821 | D4: $ | E4: 671,390 | F4: $ | G4: 647,881

Sheet 2024 k - BS
A1: ASSETS
A2: Current assets:
A3: Cash, cash equivalents, and restricted cash $ | B3: 1,514,111 | C3: $ | D3: 957,395
A4: Investment in held to maturity securities | B4: 1,908,047 | D4: 1,406,589
A5: Accounts receivable, net | B5: 785,877 | D5: 702,038
A6: Vehicle pooling costs | B6: 132,638 | D6: 123,725
A7: Inventories | B7: 43,639 | D7: 39,973
A8: Income taxes receivable | B8: — | D8: 6,574
A9: Prepaid expenses and other assets | B9: 33,872 | D9: 26,310
A10: Total current assets | B10: 4,418,184 | D10: 3,262,604
A11: Property and equipment, net | B11: 3,175,838 | D11: 2,844,339
A12: Operating lease right-of-use assets | B12: 116,301 | D12: 108,139
A13: Intangibles, net | B13: 0h0 | C13: 74,088 | E13: 62,702
A14: Goodwill | C14: 513,909 | E14: 394,289
A15: Other assets | C15: 129,444 | E15: 65,806
A16: Total assets | B16: $ | C16: 8,427,764 | D16: $ | E16: 6,737,879
B17: LIABILITIES, REDEEMABLE NONCONTROLLING INTERESTS AND STOCKHOLDERS’ EQUITY
A18: Current liabilities:
A19: Accounts payable and accrued liabilities | B19: $ | C19: 518,148 | D19: $ | E19: 440,810
A20: Deferred revenue | C20: 28,121 | E20: 26,117
A21: Income taxes payable | C21: 60,994 | E21: 4,374
A22: Current portion of operating and finance lease liabilities | C22: 21,304 | E22: 21,468
A23: Total current liabilities | C23: 628,567 | E23: 492,769
A24: Deferred income taxes | C24: 93,653 | E24: 89,492
A25: Income taxes payable | C25: 59,560 | E25: 69,193
A26: Operating and finance lease liabilities, net of current portion | C26: 97,429 | E26: 88,082
A27: Long-term debt and other liabilities, net of discount | C27: — | E27: 10,903
A28: Total liabilities | C28: 879,209 | E28: 750,439
A29: Commitments and contingencies
A30: Redeemable non-controlling interest | C30: 24,544 | E30: —
A31: Stockholders’ equity:
